{'headers': ['true_positives', 'false_positives', 'false_negatives'], 'data': [[0, 0, 0], [0, 0, 0], [0, 0, 0], [0, 0, 0], [0, 0, 0], [0, 0, 0], [0, 0, 0], [0, 0, 0], [0, 0, 0], [0, 0, 0]], 'metadata': None}
Traceback (most recent call last):
  File "C:\Users\Mattia\Documents\GitHub\auto_labeling\bin\pipeline.py", line 133, in <module>
    main(logger)
  File "C:\Users\Mattia\Documents\GitHub\auto_labeling\bin\pipeline.py", line 124, in main
    process_class(dataset, image_list, class_name, int(args.alias), args.groq, args.apikey)
  File "C:\Users\Mattia\Documents\GitHub\auto_labeling\bin\pipeline.py", line 52, in process_class
    mean_auc_score, results = metrics.get_precision_recall()
                              ^^^^^^^^^^^^^^^^^^^^^^^^^^^^^^
  File "C:\Users\Mattia\Documents\GitHub\auto_labeling\bin\metrics.py", line 36, in get_precision_recall
    auc_score = auc(recall, precision)
                ^^^^^^^^^^^^^^^^^^^^^^
  File "C:\Users\Mattia\Documents\GitHub\auto_labeling\.venv\Lib\site-packages\sklearn\utils\_param_validation.py", line 203, in wrapper
    validate_parameter_constraints(
  File "C:\Users\Mattia\Documents\GitHub\auto_labeling\.venv\Lib\site-packages\sklearn\utils\_param_validation.py", line 95, in validate_parameter_constraints
    raise InvalidParameterError(
sklearn.utils._param_validation.InvalidParameterError: The 'x' parameter of auc must be an array-like. Got 0.0 instead.